Error in task_user function
Traceback (most recent call last):
  File "/Users/atulsingh/Desktop/code/Projects/venv/lib/python2.7/site-packages/grab/spider/base.py", line 619, in execute_task_handler
    result = handler(res['grab'], res['task'])
  File "miami_metro/platformdatafetcher/blogsourcecrawlers/lookbook.py", line 125, in task_user
    site_url=website_url)
  File "/Users/atulsingh/Desktop/code/Projects/venv/lib/python2.7/site-packages/django/db/models/manager.py", line 134, in get_or_create
    return self.get_query_set().get_or_create(**kwargs)
  File "/Users/atulsingh/Desktop/code/Projects/venv/lib/python2.7/site-packages/django/db/models/query.py", line 452, in get_or_create
    obj.save(force_insert=True, using=self.db)
  File "/Users/atulsingh/Desktop/code/Projects/venv/lib/python2.7/site-packages/django/db/models/base.py", line 463, in save
    self.save_base(using=using, force_insert=force_insert, force_update=force_update)
  File "/Users/atulsingh/Desktop/code/Projects/venv/lib/python2.7/site-packages/django/db/models/base.py", line 551, in save_base
    result = manager._insert([self], fields=fields, return_id=update_pk, using=using, raw=raw)
  File "/Users/atulsingh/Desktop/code/Projects/venv/lib/python2.7/site-packages/django/db/models/manager.py", line 203, in _insert
    return insert_query(self.model, objs, fields, **kwargs)
  File "/Users/atulsingh/Desktop/code/Projects/venv/lib/python2.7/site-packages/django/db/models/query.py", line 1593, in insert_query
    return query.get_compiler(using=using).execute_sql(return_id)
  File "/Users/atulsingh/Desktop/code/Projects/venv/lib/python2.7/site-packages/django/db/models/sql/compiler.py", line 912, in execute_sql
    cursor.execute(sql, params)
  File "/Users/atulsingh/Desktop/code/Projects/venv/lib/python2.7/site-packages/django/db/backends/util.py", line 40, in execute
    return self.cursor.execute(sql, params)
  File "/Users/atulsingh/Desktop/code/Projects/venv/lib/python2.7/site-packages/django/db/backends/postgresql_psycopg2/base.py", line 52, in execute
    return self.cursor.execute(query, args)
DatabaseError: value too long for type character varying(200)

Error in task_user function
Traceback (most recent call last):
  File "/Users/atulsingh/Desktop/code/Projects/venv/lib/python2.7/site-packages/grab/spider/base.py", line 619, in execute_task_handler
    result = handler(res['grab'], res['task'])
  File "miami_metro/platformdatafetcher/blogsourcecrawlers/lookbook.py", line 125, in task_user
    site_url=website_url)
  File "/Users/atulsingh/Desktop/code/Projects/venv/lib/python2.7/site-packages/django/db/models/manager.py", line 134, in get_or_create
    return self.get_query_set().get_or_create(**kwargs)
  File "/Users/atulsingh/Desktop/code/Projects/venv/lib/python2.7/site-packages/django/db/models/query.py", line 445, in get_or_create
    return self.get(**lookup), False
  File "/Users/atulsingh/Desktop/code/Projects/venv/lib/python2.7/site-packages/django/db/models/query.py", line 361, in get
    num = len(clone)
  File "/Users/atulsingh/Desktop/code/Projects/venv/lib/python2.7/site-packages/django/db/models/query.py", line 85, in __len__
    self._result_cache = list(self.iterator())
  File "/Users/atulsingh/Desktop/code/Projects/venv/lib/python2.7/site-packages/django/db/models/query.py", line 291, in iterator
    for row in compiler.results_iter():
  File "/Users/atulsingh/Desktop/code/Projects/venv/lib/python2.7/site-packages/django/db/models/sql/compiler.py", line 763, in results_iter
    for rows in self.execute_sql(MULTI):
  File "/Users/atulsingh/Desktop/code/Projects/venv/lib/python2.7/site-packages/django/db/models/sql/compiler.py", line 818, in execute_sql
    cursor.execute(sql, params)
  File "/Users/atulsingh/Desktop/code/Projects/venv/lib/python2.7/site-packages/django/db/backends/util.py", line 40, in execute
    return self.cursor.execute(sql, params)
  File "/Users/atulsingh/Desktop/code/Projects/venv/lib/python2.7/site-packages/django/db/backends/postgresql_psycopg2/base.py", line 52, in execute
    return self.cursor.execute(query, args)
DatabaseError: current transaction is aborted, commands ignored until end of transaction block

Error in task_user function
Traceback (most recent call last):
  File "/Users/atulsingh/Desktop/code/Projects/venv/lib/python2.7/site-packages/grab/spider/base.py", line 619, in execute_task_handler
    result = handler(res['grab'], res['task'])
  File "miami_metro/platformdatafetcher/blogsourcecrawlers/lookbook.py", line 125, in task_user
    site_url=website_url)
  File "/Users/atulsingh/Desktop/code/Projects/venv/lib/python2.7/site-packages/django/db/models/manager.py", line 134, in get_or_create
    return self.get_query_set().get_or_create(**kwargs)
  File "/Users/atulsingh/Desktop/code/Projects/venv/lib/python2.7/site-packages/django/db/models/query.py", line 445, in get_or_create
    return self.get(**lookup), False
  File "/Users/atulsingh/Desktop/code/Projects/venv/lib/python2.7/site-packages/django/db/models/query.py", line 361, in get
    num = len(clone)
  File "/Users/atulsingh/Desktop/code/Projects/venv/lib/python2.7/site-packages/django/db/models/query.py", line 85, in __len__
    self._result_cache = list(self.iterator())
  File "/Users/atulsingh/Desktop/code/Projects/venv/lib/python2.7/site-packages/django/db/models/query.py", line 291, in iterator
    for row in compiler.results_iter():
  File "/Users/atulsingh/Desktop/code/Projects/venv/lib/python2.7/site-packages/django/db/models/sql/compiler.py", line 763, in results_iter
    for rows in self.execute_sql(MULTI):
  File "/Users/atulsingh/Desktop/code/Projects/venv/lib/python2.7/site-packages/django/db/models/sql/compiler.py", line 818, in execute_sql
    cursor.execute(sql, params)
  File "/Users/atulsingh/Desktop/code/Projects/venv/lib/python2.7/site-packages/django/db/backends/util.py", line 40, in execute
    return self.cursor.execute(sql, params)
  File "/Users/atulsingh/Desktop/code/Projects/venv/lib/python2.7/site-packages/django/db/backends/postgresql_psycopg2/base.py", line 52, in execute
    return self.cursor.execute(query, args)
DatabaseError: current transaction is aborted, commands ignored until end of transaction block

Error in task_user function
Traceback (most recent call last):
  File "/Users/atulsingh/Desktop/code/Projects/venv/lib/python2.7/site-packages/grab/spider/base.py", line 619, in execute_task_handler
    result = handler(res['grab'], res['task'])
  File "miami_metro/platformdatafetcher/blogsourcecrawlers/lookbook.py", line 125, in task_user
    site_url=website_url)
  File "/Users/atulsingh/Desktop/code/Projects/venv/lib/python2.7/site-packages/django/db/models/manager.py", line 134, in get_or_create
    return self.get_query_set().get_or_create(**kwargs)
  File "/Users/atulsingh/Desktop/code/Projects/venv/lib/python2.7/site-packages/django/db/models/query.py", line 445, in get_or_create
    return self.get(**lookup), False
  File "/Users/atulsingh/Desktop/code/Projects/venv/lib/python2.7/site-packages/django/db/models/query.py", line 361, in get
    num = len(clone)
  File "/Users/atulsingh/Desktop/code/Projects/venv/lib/python2.7/site-packages/django/db/models/query.py", line 85, in __len__
    self._result_cache = list(self.iterator())
  File "/Users/atulsingh/Desktop/code/Projects/venv/lib/python2.7/site-packages/django/db/models/query.py", line 291, in iterator
    for row in compiler.results_iter():
  File "/Users/atulsingh/Desktop/code/Projects/venv/lib/python2.7/site-packages/django/db/models/sql/compiler.py", line 763, in results_iter
    for rows in self.execute_sql(MULTI):
  File "/Users/atulsingh/Desktop/code/Projects/venv/lib/python2.7/site-packages/django/db/models/sql/compiler.py", line 818, in execute_sql
    cursor.execute(sql, params)
  File "/Users/atulsingh/Desktop/code/Projects/venv/lib/python2.7/site-packages/django/db/backends/util.py", line 40, in execute
    return self.cursor.execute(sql, params)
  File "/Users/atulsingh/Desktop/code/Projects/venv/lib/python2.7/site-packages/django/db/backends/postgresql_psycopg2/base.py", line 52, in execute
    return self.cursor.execute(query, args)
DatabaseError: current transaction is aborted, commands ignored until end of transaction block

Error in task_user function
Traceback (most recent call last):
  File "/Users/atulsingh/Desktop/code/Projects/venv/lib/python2.7/site-packages/grab/spider/base.py", line 619, in execute_task_handler
    result = handler(res['grab'], res['task'])
  File "miami_metro/platformdatafetcher/blogsourcecrawlers/lookbook.py", line 125, in task_user
    site_url=website_url)
  File "/Users/atulsingh/Desktop/code/Projects/venv/lib/python2.7/site-packages/django/db/models/manager.py", line 134, in get_or_create
    return self.get_query_set().get_or_create(**kwargs)
  File "/Users/atulsingh/Desktop/code/Projects/venv/lib/python2.7/site-packages/django/db/models/query.py", line 445, in get_or_create
    return self.get(**lookup), False
  File "/Users/atulsingh/Desktop/code/Projects/venv/lib/python2.7/site-packages/django/db/models/query.py", line 361, in get
    num = len(clone)
  File "/Users/atulsingh/Desktop/code/Projects/venv/lib/python2.7/site-packages/django/db/models/query.py", line 85, in __len__
    self._result_cache = list(self.iterator())
  File "/Users/atulsingh/Desktop/code/Projects/venv/lib/python2.7/site-packages/django/db/models/query.py", line 291, in iterator
    for row in compiler.results_iter():
  File "/Users/atulsingh/Desktop/code/Projects/venv/lib/python2.7/site-packages/django/db/models/sql/compiler.py", line 763, in results_iter
    for rows in self.execute_sql(MULTI):
  File "/Users/atulsingh/Desktop/code/Projects/venv/lib/python2.7/site-packages/django/db/models/sql/compiler.py", line 818, in execute_sql
    cursor.execute(sql, params)
  File "/Users/atulsingh/Desktop/code/Projects/venv/lib/python2.7/site-packages/django/db/backends/util.py", line 40, in execute
    return self.cursor.execute(sql, params)
  File "/Users/atulsingh/Desktop/code/Projects/venv/lib/python2.7/site-packages/django/db/backends/postgresql_psycopg2/base.py", line 52, in execute
    return self.cursor.execute(query, args)
DatabaseError: current transaction is aborted, commands ignored until end of transaction block

Error in task_user function
Traceback (most recent call last):
  File "/Users/atulsingh/Desktop/code/Projects/venv/lib/python2.7/site-packages/grab/spider/base.py", line 619, in execute_task_handler
    result = handler(res['grab'], res['task'])
  File "miami_metro/platformdatafetcher/blogsourcecrawlers/lookbook.py", line 125, in task_user
    site_url=website_url)
  File "/Users/atulsingh/Desktop/code/Projects/venv/lib/python2.7/site-packages/django/db/models/manager.py", line 134, in get_or_create
    return self.get_query_set().get_or_create(**kwargs)
  File "/Users/atulsingh/Desktop/code/Projects/venv/lib/python2.7/site-packages/django/db/models/query.py", line 445, in get_or_create
    return self.get(**lookup), False
  File "/Users/atulsingh/Desktop/code/Projects/venv/lib/python2.7/site-packages/django/db/models/query.py", line 361, in get
    num = len(clone)
  File "/Users/atulsingh/Desktop/code/Projects/venv/lib/python2.7/site-packages/django/db/models/query.py", line 85, in __len__
    self._result_cache = list(self.iterator())
  File "/Users/atulsingh/Desktop/code/Projects/venv/lib/python2.7/site-packages/django/db/models/query.py", line 291, in iterator
    for row in compiler.results_iter():
  File "/Users/atulsingh/Desktop/code/Projects/venv/lib/python2.7/site-packages/django/db/models/sql/compiler.py", line 763, in results_iter
    for rows in self.execute_sql(MULTI):
  File "/Users/atulsingh/Desktop/code/Projects/venv/lib/python2.7/site-packages/django/db/models/sql/compiler.py", line 818, in execute_sql
    cursor.execute(sql, params)
  File "/Users/atulsingh/Desktop/code/Projects/venv/lib/python2.7/site-packages/django/db/backends/util.py", line 40, in execute
    return self.cursor.execute(sql, params)
  File "/Users/atulsingh/Desktop/code/Projects/venv/lib/python2.7/site-packages/django/db/backends/postgresql_psycopg2/base.py", line 52, in execute
    return self.cursor.execute(query, args)
DatabaseError: current transaction is aborted, commands ignored until end of transaction block

Error in task_user function
Traceback (most recent call last):
  File "/Users/atulsingh/Desktop/code/Projects/venv/lib/python2.7/site-packages/grab/spider/base.py", line 619, in execute_task_handler
    result = handler(res['grab'], res['task'])
  File "miami_metro/platformdatafetcher/blogsourcecrawlers/lookbook.py", line 125, in task_user
    site_url=website_url)
  File "/Users/atulsingh/Desktop/code/Projects/venv/lib/python2.7/site-packages/django/db/models/manager.py", line 134, in get_or_create
    return self.get_query_set().get_or_create(**kwargs)
  File "/Users/atulsingh/Desktop/code/Projects/venv/lib/python2.7/site-packages/django/db/models/query.py", line 445, in get_or_create
    return self.get(**lookup), False
  File "/Users/atulsingh/Desktop/code/Projects/venv/lib/python2.7/site-packages/django/db/models/query.py", line 361, in get
    num = len(clone)
  File "/Users/atulsingh/Desktop/code/Projects/venv/lib/python2.7/site-packages/django/db/models/query.py", line 85, in __len__
    self._result_cache = list(self.iterator())
  File "/Users/atulsingh/Desktop/code/Projects/venv/lib/python2.7/site-packages/django/db/models/query.py", line 291, in iterator
    for row in compiler.results_iter():
  File "/Users/atulsingh/Desktop/code/Projects/venv/lib/python2.7/site-packages/django/db/models/sql/compiler.py", line 763, in results_iter
    for rows in self.execute_sql(MULTI):
  File "/Users/atulsingh/Desktop/code/Projects/venv/lib/python2.7/site-packages/django/db/models/sql/compiler.py", line 818, in execute_sql
    cursor.execute(sql, params)
  File "/Users/atulsingh/Desktop/code/Projects/venv/lib/python2.7/site-packages/django/db/backends/util.py", line 40, in execute
    return self.cursor.execute(sql, params)
  File "/Users/atulsingh/Desktop/code/Projects/venv/lib/python2.7/site-packages/django/db/backends/postgresql_psycopg2/base.py", line 52, in execute
    return self.cursor.execute(query, args)
DatabaseError: current transaction is aborted, commands ignored until end of transaction block

Error in task_user function
Traceback (most recent call last):
  File "/Users/atulsingh/Desktop/code/Projects/venv/lib/python2.7/site-packages/grab/spider/base.py", line 619, in execute_task_handler
    result = handler(res['grab'], res['task'])
  File "miami_metro/platformdatafetcher/blogsourcecrawlers/lookbook.py", line 125, in task_user
    site_url=website_url)
  File "/Users/atulsingh/Desktop/code/Projects/venv/lib/python2.7/site-packages/django/db/models/manager.py", line 134, in get_or_create
    return self.get_query_set().get_or_create(**kwargs)
  File "/Users/atulsingh/Desktop/code/Projects/venv/lib/python2.7/site-packages/django/db/models/query.py", line 445, in get_or_create
    return self.get(**lookup), False
  File "/Users/atulsingh/Desktop/code/Projects/venv/lib/python2.7/site-packages/django/db/models/query.py", line 361, in get
    num = len(clone)
  File "/Users/atulsingh/Desktop/code/Projects/venv/lib/python2.7/site-packages/django/db/models/query.py", line 85, in __len__
    self._result_cache = list(self.iterator())
  File "/Users/atulsingh/Desktop/code/Projects/venv/lib/python2.7/site-packages/django/db/models/query.py", line 291, in iterator
    for row in compiler.results_iter():
  File "/Users/atulsingh/Desktop/code/Projects/venv/lib/python2.7/site-packages/django/db/models/sql/compiler.py", line 763, in results_iter
    for rows in self.execute_sql(MULTI):
  File "/Users/atulsingh/Desktop/code/Projects/venv/lib/python2.7/site-packages/django/db/models/sql/compiler.py", line 818, in execute_sql
    cursor.execute(sql, params)
  File "/Users/atulsingh/Desktop/code/Projects/venv/lib/python2.7/site-packages/django/db/backends/util.py", line 40, in execute
    return self.cursor.execute(sql, params)
  File "/Users/atulsingh/Desktop/code/Projects/venv/lib/python2.7/site-packages/django/db/backends/postgresql_psycopg2/base.py", line 52, in execute
    return self.cursor.execute(query, args)
DatabaseError: current transaction is aborted, commands ignored until end of transaction block

Error in task_user function
Traceback (most recent call last):
  File "/Users/atulsingh/Desktop/code/Projects/venv/lib/python2.7/site-packages/grab/spider/base.py", line 619, in execute_task_handler
    result = handler(res['grab'], res['task'])
  File "miami_metro/platformdatafetcher/blogsourcecrawlers/lookbook.py", line 125, in task_user
    site_url=website_url)
  File "/Users/atulsingh/Desktop/code/Projects/venv/lib/python2.7/site-packages/django/db/models/manager.py", line 134, in get_or_create
    return self.get_query_set().get_or_create(**kwargs)
  File "/Users/atulsingh/Desktop/code/Projects/venv/lib/python2.7/site-packages/django/db/models/query.py", line 445, in get_or_create
    return self.get(**lookup), False
  File "/Users/atulsingh/Desktop/code/Projects/venv/lib/python2.7/site-packages/django/db/models/query.py", line 361, in get
    num = len(clone)
  File "/Users/atulsingh/Desktop/code/Projects/venv/lib/python2.7/site-packages/django/db/models/query.py", line 85, in __len__
    self._result_cache = list(self.iterator())
  File "/Users/atulsingh/Desktop/code/Projects/venv/lib/python2.7/site-packages/django/db/models/query.py", line 291, in iterator
    for row in compiler.results_iter():
  File "/Users/atulsingh/Desktop/code/Projects/venv/lib/python2.7/site-packages/django/db/models/sql/compiler.py", line 763, in results_iter
    for rows in self.execute_sql(MULTI):
  File "/Users/atulsingh/Desktop/code/Projects/venv/lib/python2.7/site-packages/django/db/models/sql/compiler.py", line 818, in execute_sql
    cursor.execute(sql, params)
  File "/Users/atulsingh/Desktop/code/Projects/venv/lib/python2.7/site-packages/django/db/backends/util.py", line 40, in execute
    return self.cursor.execute(sql, params)
  File "/Users/atulsingh/Desktop/code/Projects/venv/lib/python2.7/site-packages/django/db/backends/postgresql_psycopg2/base.py", line 52, in execute
    return self.cursor.execute(query, args)
DatabaseError: current transaction is aborted, commands ignored until end of transaction block

Error in task_user function
Traceback (most recent call last):
  File "/Users/atulsingh/Desktop/code/Projects/venv/lib/python2.7/site-packages/grab/spider/base.py", line 619, in execute_task_handler
    result = handler(res['grab'], res['task'])
  File "miami_metro/platformdatafetcher/blogsourcecrawlers/lookbook.py", line 125, in task_user
    site_url=website_url)
  File "/Users/atulsingh/Desktop/code/Projects/venv/lib/python2.7/site-packages/django/db/models/manager.py", line 134, in get_or_create
    return self.get_query_set().get_or_create(**kwargs)
  File "/Users/atulsingh/Desktop/code/Projects/venv/lib/python2.7/site-packages/django/db/models/query.py", line 445, in get_or_create
    return self.get(**lookup), False
  File "/Users/atulsingh/Desktop/code/Projects/venv/lib/python2.7/site-packages/django/db/models/query.py", line 361, in get
    num = len(clone)
  File "/Users/atulsingh/Desktop/code/Projects/venv/lib/python2.7/site-packages/django/db/models/query.py", line 85, in __len__
    self._result_cache = list(self.iterator())
  File "/Users/atulsingh/Desktop/code/Projects/venv/lib/python2.7/site-packages/django/db/models/query.py", line 291, in iterator
    for row in compiler.results_iter():
  File "/Users/atulsingh/Desktop/code/Projects/venv/lib/python2.7/site-packages/django/db/models/sql/compiler.py", line 763, in results_iter
    for rows in self.execute_sql(MULTI):
  File "/Users/atulsingh/Desktop/code/Projects/venv/lib/python2.7/site-packages/django/db/models/sql/compiler.py", line 818, in execute_sql
    cursor.execute(sql, params)
  File "/Users/atulsingh/Desktop/code/Projects/venv/lib/python2.7/site-packages/django/db/backends/util.py", line 40, in execute
    return self.cursor.execute(sql, params)
  File "/Users/atulsingh/Desktop/code/Projects/venv/lib/python2.7/site-packages/django/db/backends/postgresql_psycopg2/base.py", line 52, in execute
    return self.cursor.execute(query, args)
DatabaseError: current transaction is aborted, commands ignored until end of transaction block

Error in task_user function
Traceback (most recent call last):
  File "/Users/atulsingh/Desktop/code/Projects/venv/lib/python2.7/site-packages/grab/spider/base.py", line 619, in execute_task_handler
    result = handler(res['grab'], res['task'])
  File "miami_metro/platformdatafetcher/blogsourcecrawlers/lookbook.py", line 125, in task_user
    site_url=website_url)
  File "/Users/atulsingh/Desktop/code/Projects/venv/lib/python2.7/site-packages/django/db/models/manager.py", line 134, in get_or_create
    return self.get_query_set().get_or_create(**kwargs)
  File "/Users/atulsingh/Desktop/code/Projects/venv/lib/python2.7/site-packages/django/db/models/query.py", line 445, in get_or_create
    return self.get(**lookup), False
  File "/Users/atulsingh/Desktop/code/Projects/venv/lib/python2.7/site-packages/django/db/models/query.py", line 361, in get
    num = len(clone)
  File "/Users/atulsingh/Desktop/code/Projects/venv/lib/python2.7/site-packages/django/db/models/query.py", line 85, in __len__
    self._result_cache = list(self.iterator())
  File "/Users/atulsingh/Desktop/code/Projects/venv/lib/python2.7/site-packages/django/db/models/query.py", line 291, in iterator
    for row in compiler.results_iter():
  File "/Users/atulsingh/Desktop/code/Projects/venv/lib/python2.7/site-packages/django/db/models/sql/compiler.py", line 763, in results_iter
    for rows in self.execute_sql(MULTI):
  File "/Users/atulsingh/Desktop/code/Projects/venv/lib/python2.7/site-packages/django/db/models/sql/compiler.py", line 818, in execute_sql
    cursor.execute(sql, params)
  File "/Users/atulsingh/Desktop/code/Projects/venv/lib/python2.7/site-packages/django/db/backends/util.py", line 40, in execute
    return self.cursor.execute(sql, params)
  File "/Users/atulsingh/Desktop/code/Projects/venv/lib/python2.7/site-packages/django/db/backends/postgresql_psycopg2/base.py", line 52, in execute
    return self.cursor.execute(query, args)
DatabaseError: current transaction is aborted, commands ignored until end of transaction block

Error in task_user function
Traceback (most recent call last):
  File "/Users/atulsingh/Desktop/code/Projects/venv/lib/python2.7/site-packages/grab/spider/base.py", line 619, in execute_task_handler
    result = handler(res['grab'], res['task'])
  File "miami_metro/platformdatafetcher/blogsourcecrawlers/lookbook.py", line 125, in task_user
    site_url=website_url)
  File "/Users/atulsingh/Desktop/code/Projects/venv/lib/python2.7/site-packages/django/db/models/manager.py", line 134, in get_or_create
    return self.get_query_set().get_or_create(**kwargs)
  File "/Users/atulsingh/Desktop/code/Projects/venv/lib/python2.7/site-packages/django/db/models/query.py", line 445, in get_or_create
    return self.get(**lookup), False
  File "/Users/atulsingh/Desktop/code/Projects/venv/lib/python2.7/site-packages/django/db/models/query.py", line 361, in get
    num = len(clone)
  File "/Users/atulsingh/Desktop/code/Projects/venv/lib/python2.7/site-packages/django/db/models/query.py", line 85, in __len__
    self._result_cache = list(self.iterator())
  File "/Users/atulsingh/Desktop/code/Projects/venv/lib/python2.7/site-packages/django/db/models/query.py", line 291, in iterator
    for row in compiler.results_iter():
  File "/Users/atulsingh/Desktop/code/Projects/venv/lib/python2.7/site-packages/django/db/models/sql/compiler.py", line 763, in results_iter
    for rows in self.execute_sql(MULTI):
  File "/Users/atulsingh/Desktop/code/Projects/venv/lib/python2.7/site-packages/django/db/models/sql/compiler.py", line 818, in execute_sql
    cursor.execute(sql, params)
  File "/Users/atulsingh/Desktop/code/Projects/venv/lib/python2.7/site-packages/django/db/backends/util.py", line 40, in execute
    return self.cursor.execute(sql, params)
  File "/Users/atulsingh/Desktop/code/Projects/venv/lib/python2.7/site-packages/django/db/backends/postgresql_psycopg2/base.py", line 52, in execute
    return self.cursor.execute(query, args)
DatabaseError: current transaction is aborted, commands ignored until end of transaction block

Error in task_user function
Traceback (most recent call last):
  File "/Users/atulsingh/Desktop/code/Projects/venv/lib/python2.7/site-packages/grab/spider/base.py", line 619, in execute_task_handler
    result = handler(res['grab'], res['task'])
  File "miami_metro/platformdatafetcher/blogsourcecrawlers/lookbook.py", line 125, in task_user
    site_url=website_url)
  File "/Users/atulsingh/Desktop/code/Projects/venv/lib/python2.7/site-packages/django/db/models/manager.py", line 134, in get_or_create
    return self.get_query_set().get_or_create(**kwargs)
  File "/Users/atulsingh/Desktop/code/Projects/venv/lib/python2.7/site-packages/django/db/models/query.py", line 445, in get_or_create
    return self.get(**lookup), False
  File "/Users/atulsingh/Desktop/code/Projects/venv/lib/python2.7/site-packages/django/db/models/query.py", line 361, in get
    num = len(clone)
  File "/Users/atulsingh/Desktop/code/Projects/venv/lib/python2.7/site-packages/django/db/models/query.py", line 85, in __len__
    self._result_cache = list(self.iterator())
  File "/Users/atulsingh/Desktop/code/Projects/venv/lib/python2.7/site-packages/django/db/models/query.py", line 291, in iterator
    for row in compiler.results_iter():
  File "/Users/atulsingh/Desktop/code/Projects/venv/lib/python2.7/site-packages/django/db/models/sql/compiler.py", line 763, in results_iter
    for rows in self.execute_sql(MULTI):
  File "/Users/atulsingh/Desktop/code/Projects/venv/lib/python2.7/site-packages/django/db/models/sql/compiler.py", line 818, in execute_sql
    cursor.execute(sql, params)
  File "/Users/atulsingh/Desktop/code/Projects/venv/lib/python2.7/site-packages/django/db/backends/util.py", line 40, in execute
    return self.cursor.execute(sql, params)
  File "/Users/atulsingh/Desktop/code/Projects/venv/lib/python2.7/site-packages/django/db/backends/postgresql_psycopg2/base.py", line 52, in execute
    return self.cursor.execute(query, args)
DatabaseError: current transaction is aborted, commands ignored until end of transaction block

